Workbook
Name Timeline_Date: #N/A
Name Timeline_Date1: #N/A

Sheet DASHBOARD
A1: Learning and Development Dash Board
Z6: Participation rate
B7: Total Programs | D7: Training Days | F7: Total Participants | H7: Training Hours | L7: NPS Overall Score | N7: Facilitators Performance | Q7: Knowledge Relevance | T7: Activity Effectivness | W7: Logistics Effectivness | Z7: =F8/192 -> 0.66666667 | AA7: Customised | AB7: ='Program Pivots'!B23 -> 0.53125
B8: =GETPIVOTDATA("[Measures].[Distinct Count of Program Name 2]",'Program Pivots'!$S$3) -> 24 | D8: =GETPIVOTDATA("[Measures].[Sum of No.of sessions 2]",'Program Pivots'!$P$3) -> 40 | F8: =GETPIVOTDATA("[Measures].[Distinct Count of Name 2]",'Program Pivots'!$G$3) -> 128 | H8: ='Program Pivots'!B5 -> 130.5 | L8: =GETPIVOTDATA("[Measures].[Average of NPS]",'Evaluation Pivots'!$D$3) -> 0.92727273 | O8: =GETPIVOTDATA("[Measures].[Average of FACILITATOR PERFORMANCE]",'Evaluation Pivots'!$A$3) -> 1 | Q8: =GETPIVOTDATA("[Measures].[Average of KNOWLEDGE RELVEANCE 2]",'Evaluation Pivots'!$D$3) -> 1 | T8: =GETPIVOTDATA("[Measures].[Average of ACTIVITY EFFECTIVNESS]",'Evaluation Pivots'!$D$3) -> 0.98181818 | W8: =GETPIVOTDATA("[Measures].[Average of LOGISTICS EFFECTIVNESS]",'Evaluation Pivots'!$D$3) -> 0.96363636 | AA8: Public Calender | AB8: ='Program Pivots'!B19 -> 0.33854167

Sheet Program Pivots
B1: HC | C1: 192 | J1: Date | K1: All
A2: Main L&D Data (YTD) | D2: Internal vs External Training | G2: Participation per Program | J2: Participation per Sector | M2: Training Hours | P2: Training Days | S2: Monthly Track | X2: Trainer Profile | AC2: Enrollment vs Participation per Program | AG2: Unique User count | AJ2: Learning Hours per Participant | AM2: PC vs Customised | AR2: Customised Track
A3: No.of Programs | B3: =GETPIVOTDATA("[Measures].[Distinct Count of Program Name 2]",$D$3) -> 25 | D3: Row Labels | E3: Distinct Count of Program Name | G3: Row Labels | H3: Distinct Count of Name | J3: Row Labels | K3: Distinct Count of Name | M3: Row Labels | N3: Sum of Program Duration/hrs | P3: Row Labels | Q3: Sum of No.of sessions | S3: Row Labels | T3: Training Days | U3: Participation | V3: No. of Programs | X3: Row Labels | Y3: Training Days | Z3: Programs | AC3: Row Labels | AD3: Participation | AE3: Enrollments | AG3: Row Labels | AH3: Distinct Count of Name | AJ3: Row Labels | AK3: Sum of Learning Hrs | AM3: Row Labels | AN3: Distinct Count of Name | AO3: Sum of No.of sessions | AP3: Sum of Learning Hrs | AR3: Row Labels | AS3: Count of Program Name
A4: No. of Participants | B4: =GETPIVOTDATA("[Measures].[Distinct Count of Name 2]",$G$3) -> 128 | D4: External | E4: 3 | G4: Ai 4 Marq - AI Foundations - Wave 2 | H4: 5 | J4: #N/A | K4: 2 | M4: Ai 4 Marq - AI Foundations - Wave 2 | N4: 2 | P4: Ai 4 Marq - AI Foundations - Wave 2 | Q4: 1 | S4: Feb | T4: 7 | U4: 18 | V4: 6 | X4: Ahmed Elshiaty | Y4: 10 | Z4: 5 | AC4: Ai 4 Marq - AI Foundations - Wave 2 | AD4: 5 | AE4: 17 | AG4: Abdelaziz Youssef Abo El Wafa Mohamed | AH4: 1 | AJ4: Abdelaziz Youssef Abo El Wafa Mohamed | AK4: 15 | AM4: Customised | AN4: 102 | AO4: 19 | AP4: 867.5 | AR4: Customised
A5: Training Hrs | B5: =GETPIVOTDATA("[Measures].[Sum of Program Duration/hrs]",$M$3) -> 130.5 | D5: Internal | E5: 22 | G5: Ai 4 Marq - Level 1 | H5: 17 | J5: CCE | K5: 3 | M5: Ai 4 Marq - Level 1 | N5: 2 | P5: Ai 4 Marq - Level 1 | Q5: 1 | S5: Mar | T5: 3 | U5: 16 | V5: 3 | X5: Ahmed Magdi | Y5: 2 | Z5: 1 | AC5: Ai 4 Marq - Level 1 | AD5: 17 | AE5: 26 | AG5: Abdelrahman Ismail Abdallah Elshahat | AH5: 1 | AJ5: Abdelrahman Ismail Abdallah Elshahat | AK5: 6 | AM5: Public Calender | AN5: 65 | AO5: 21 | AP5: 518.5 | AR5: CCE | AS5: 2
A6: Training Days | B6: =GETPIVOTDATA("[Measures].[Sum of No.of sessions 2]",$P$3) -> 40 | D6: Grand Total | E6: 25 | G6: AI for real estate (Projects-D&I) | H6: 23 | J6: Commercial | K6: 21 | M6: AI for real estate (Projects-D&I) | N6: 8 | P6: AI for real estate (Projects-D&I) | Q6: 2 | S6: Apr | T6: 3 | U6: 24 | V6: 2 | X6: Amr Alaa | Y6: 11 | Z6: 8 | AC6: AI for real estate (Projects-D&I) | AD6: 23 | AE6: 46 | AG6: Abdelrahman Khaled Saber Mohamed | AH6: 1 | AJ6: Abdelrahman Khaled Saber Mohamed | AK6: 16 | AM6: Grand Total | AN6: 128 | AO6: 40 | AP6: 1386 | AR6: Finance | AS6: 2
A7: Participation Rate | B7: =GETPIVOTDATA("[Measures].[Distinct Count of Name 2]",$G$3)/192 -> 0.66666667 | G7: Customer Focus | H7: 10 | J7: Communities & Clients Excellence | K7: 29 | M7: Customer Focus | N7: 9 | P7: Customer Focus | Q7: 2 | S7: May | T7: 6 | U7: 48 | V7: 4 | X7: Aya Sameh | Y7: 8 | Z7: 6 | AC7: Customer Focus | AD7: 10 | AE7: 10 | AG7: Abdelrahman Mohamed Saad Ahmed | AH7: 1 | AJ7: Abdelrahman Mohamed Saad Ahmed | AK7: 16.5 | AR7: I&D | AS7: 1
A8: Internal % | B8: =((GETPIVOTDATA("[Measures].[Distinct Count of Program Name 2]",$D$3,"[Range].[Internal/External]","[Range].[Internal/External].&[Internal]")/GETPIVOTDATA("[Measures].[Distinct Count of Program Name 2]",$D$3))) -> 0.88 | G8: Customer XP Cycle-CCE ONLY | H8: 13 | J8: Development & Innovation | K8: 18 | M8: Customer XP Cycle-CCE ONLY | N8: 6 | P8: Customer XP Cycle-CCE ONLY | Q8: 2 | S8: Jun | T8: 12 | U8: 64 | V8: 6 | X8: Belton Academy | Y8: 2 | Z8: 1 | AC8: Customer XP Cycle-CCE ONLY | AD8: 13 | AE8: 15 | AG8: Ahmad Mohamed Ahmad Mohamed Mansour | AH8: 1 | AJ8: Ahmad Mohamed Ahmad Mohamed Mansour | AK8: 5 | AR8: L&D | AS8: 1
A9: Compiled Participation | B9: 98 | G9: Excel 101 | H9: 11 | J9: Finance | K9: 14 | M9: Excel 101 | N9: 13.5 | P9: Excel 101 | Q9: 4 | S9: Jul | T9: 7 | U9: 41 | V9: 4 | X9: Moaataz | Y9: 4 | Z9: 1 | AC9: Excel 101 | AD9: 11 | AE9: 14 | AG9: Ahmed Abdel Hakim | AH9: 1 | AJ9: Ahmed Abdel Hakim | AK9: 5 | AR9: Projects | AS9: 2
A10: Linked In | B10: 12 | D10: Programs per Focus | G10: Goal Setting &Building Habits -HS | H10: 9 | J10: HR Business Partner | K10: 2 | M10: Goal Setting &Building Habits -HS | N10: 5 | P10: Goal Setting &Building Habits -HS | Q10: 1 | S10: Grand Total | T10: 38 | U10: 128 | V10: 24 | X10: Omar Ali | Y10: 2 | Z10: 2 | AC10: Goal Setting &Building Habits -HS | AD10: 9 | AE10: 12 | AG10: Ahmed elsayed elsayed elshiaty | AH10: 1 | AJ10: Ahmed elsayed elsayed elshiaty | AK10: 5 | AR10: Sales | AS10: 5
D11: Row Labels | E11: Count of Program Name | G11: Hard Talks | H11: 5 | J11: Human Resources | K11: 9 | M11: Hard Talks | N11: 6 | P11: Hard Talks | Q11: 2 | X11: Yehia Maklad | Y11: 1 | Z11: 1 | AC11: Hard Talks | AD11: 5 | AE11: 14 | AG11: Ahmed Gamal Mostafa Kamel | AH11: 1 | AJ11: Ahmed Gamal Mostafa Kamel | AK11: 23 | AR11: Public Calender
D12: Customised | E12: 13 | G12: HPI | H12: 6 | J12: Investment | K12: 2 | M12: HPI | N12: 5 | P12: HPI | Q12: 1 | X12: Grand Total | Y12: 40 | Z12: 25 | AC12: HPI | AD12: 6 | AE12: 6 | AG12: Ahmed kamal El Din Hassan El Khateeb | AH12: 1 | AJ12: Ahmed kamal El Din Hassan El Khateeb | AK12: 11 | AR12: (blank) | AS12: 12
D13: Public Calender | E13: 12 | G13: inside out | H13: 6 | J13: Marketing | K13: 1 | M13: inside out | N13: 6 | P13: inside out | Q13: 2 | AC13: inside out | AD13: 6 | AE13: 6 | AG13: Ahmed Khaled Kamal Ibrahim | AH13: 1 | AJ13: Ahmed Khaled Kamal Ibrahim | AK13: 15 | AR13: Grand Total | AS13: 25
D14: Grand Total | E14: 25 | G14: Island of Seacrets-(Finance Dept) | H14: 11 | J14: Marketing & PR | K14: 6 | M14: Island of Seacrets-(Finance Dept) | N14: 2.5 | P14: Island of Seacrets-(Finance Dept) | Q14: 1 | AC14: Island of Seacrets-(Finance Dept) | AD14: 11 | AE14: 16 | AG14: Ahmed Magdy Fekry Elhagaa | AH14: 1 | AJ14: Ahmed Magdy Fekry Elhagaa | AK14: 5
G15: LinkedIn Learning Kick-Off Session | H15: 16 | J15: Projects | K15: 21 | M15: LinkedIn Learning Kick-Off Session | N15: 1 | P15: LinkedIn Learning Kick-Off Session | Q15: 1 | AC15: LinkedIn Learning Kick-Off Session | AD15: 16 | AE15: 23 | AG15: Ahmed Medhat Sayed Baioumy el Atbany | AH15: 1 | AJ15: Ahmed Medhat Sayed Baioumy el Atbany | AK15: 14
G16: Master The Shift | H16: 10 | J16: Treasury | K16: 7 | M16: Master The Shift | N16: 4.5 | P16: Master The Shift | Q16: 2 | AC16: Master The Shift | AD16: 10 | AE16: 13 | AG16: Ahmed mohamed AboelMagd Eldardiri | AH16: 1 | AJ16: Ahmed mohamed AboelMagd Eldardiri | AK16: 9
G17: Parenting 101 | H17: 9 | J17: Grand Total | K17: 128 | M17: Parenting 101 | N17: 4 | P17: Parenting 101 | Q17: 1 | AC17: Parenting 101 | AD17: 9 | AE17: 10 | AG17: Ahmed Mohamed Ahmed Salem | AH17: 1 | AJ17: Ahmed Mohamed Ahmed Salem | AK17: 9
A18: Public Calender | G18: Presentation Skills-HS | H18: 7 | M18: Presentation Skills-HS | N18: 5 | P18: Presentation Skills-HS | Q18: 1 | AC18: Presentation Skills-HS | AD18: 7 | AE18: 12 | AG18: Ahmed Mohamed Gamal Mohamed Mohamed Youssef Elbehery | AH18: 1 | AJ18: Ahmed Mohamed Gamal Mohamed Mohamed Youssef Elbehery | AK18: 1
A19: Participation Rate | B19: =GETPIVOTDATA("[Measures].[Distinct Count of Name 2]",$D$20,"[Range].[Participation PC/Cust]","[Range].[Participation PC/Cust].&[Public Calender]")/C1 -> 0.33854167 | D19: Participation per Focus | G19: Sales Skills 1-HS | H19: 9 | M19: Sales Skills 1-HS | N19: 5 | P19: Sales Skills 1-HS | Q19: 1 | AC19: Sales Skills 1-HS | AD19: 9 | AE19: 12 | AG19: Ahmed Raouf Abdel Menaam Hanafy | AH19: 1 | AJ19: Ahmed Raouf Abdel Menaam Hanafy | AK19: 8
A20: No.of Public Calender Topics | B20: =GETPIVOTDATA("[Measures].[Count of Program Name 2]",$D$11,"[Range].[PC/Cust (Per Topic)]","[Range].[PC/Cust (Per Topic)].&[Public Calender]") -> 12 | D20: Row Labels | E20: Distinct Count of Name | G20: Sales Skills 2-HS | H20: 9 | M20: Sales Skills 2-HS | N20: 5 | P20: Sales Skills 2-HS | Q20: 1 | AC20: Sales Skills 2-HS | AD20: 9 | AE20: 12 | AG20: Ahmed Saber Abdelrady Mohamed | AH20: 1 | AJ20: Ahmed Saber Abdelrady Mohamed | AK20: 20
D21: Customised | E21: 102 | G21: Self Discovery Lab | H21: 6 | M21: Self Discovery Lab | N21: 4 | P21: Self Discovery Lab | Q21: 2 | AC21: Self Discovery Lab | AD21: 6 | AE21: 10 | AG21: Ahmed Samir Galal Elelemy Ahmed | AH21: 1 | AJ21: Ahmed Samir Galal Elelemy Ahmed | AK21: 30
A22: Customised | D22: Public Calender | E22: 65 | G22: Slide Design | H22: 1 | M22: Slide Design | N22: 6 | P22: Slide Design | Q22: 2 | AC22: Slide Design | AD22: 1 | AE22: 8 | AG22: Ahmed Shawky Abdo El Bastawisy El Sahy | AH22: 1 | AJ22: Ahmed Shawky Abdo El Bastawisy El Sahy | AK22: 7
A23: Participation Rate | B23: =GETPIVOTDATA("[Measures].[Distinct Count of Name 2]",$D$20,"[Range].[Participation PC/Cust]","[Range].[Participation PC/Cust].&[Customised]")/C1 -> 0.53125 | D23: Grand Total | E23: 128 | G23: Story Craft | H23: 13 | M23: Story Craft | N23: 4 | P23: Story Craft | Q23: 2 | AC23: Story Craft | AD23: 13 | AE23: 20 | AG23: Ahmed Sobhy Mohamed Bayoumi | AH23: 1 | AJ23: Ahmed Sobhy Mohamed Bayoumi | AK23: 9
A24: No.of Cust Programs | B24: =GETPIVOTDATA("[Measures].[Count of Program Name 2]",$D$11,"[Range].[PC/Cust (Per Topic)]","[Range].[PC/Cust (Per Topic)].&[Customised]") -> 13 | G24: The Connected Leader | H24: 23 | M24: The Connected Leader | N24: 6 | P24: The Connected Leader | Q24: 2 | AC24: The Connected Leader | AD24: 23 | AE24: 34 | AG24: Aida Fouad Mohamed Kamal | AH24: 1 | AJ24: Aida Fouad Mohamed Kamal | AK24: 2
G25: The Influence Map | H25: 21 | M25: The Influence Map | N25: 6 | P25: The Influence Map | Q25: 2 | AC25: The Influence Map | AD25: 21 | AE25: 25 | AG25: Alaa Essam Mohamed Ibrahim | AH25: 1 | AJ25: Alaa Essam Mohamed Ibrahim | AK25: 9
G26: The Influence Map (Projects) | H26: 20 | M26: The Influence Map (Projects) | N26: 6 | P26: The Influence Map (Projects) | Q26: 2 | AC26: The Influence Map (Projects) | AD26: 20 | AE26: 27 | AG26: Amira Tarek Mohamed Abdelmutaal Ali El Sherkawy | AH26: 1 | AJ26: Amira Tarek Mohamed Abdelmutaal Ali El Sherkawy | AK26: 15
G27: Think Human | H27: 3 | M27: Think Human | N27: 4 | P27: Think Human | Q27: 1 | AC27: Think Human | AD27: 3 | AE27: 9 | AG27: Amr Alaa Eldin Maged Ahmed | AH27: 1 | AJ27: Amr Alaa Eldin Maged Ahmed | AK27: 5
G28: Time &Self Management -HS | H28: 6 | M28: Time &Self Management -HS | N28: 5 | P28: Time &Self Management -HS | Q28: 1 | AC28: Time &Self Management -HS | AD28: 6 | AE28: 12 | AG28: Amr Ali Abdelwahab Sobh | AH28: 1 | AJ28: Amr Ali Abdelwahab Sobh | AK28: 14.5
G29: Grand Total | H29: 128 | M29: Grand Total | N29: 130.5 | P29: Grand Total | Q29: 40 | AC29: Grand Total | AD29: 128 | AE29: 409 | AG29: Amr Ali Mahmoud Elhanbaly | AH29: 1 | AJ29: Amr Ali Mahmoud Elhanbaly | AK29: 25
AG30: Amr Hani Mohamed Abdel Latif | AH30: 1 | AJ30: Amr Hani Mohamed Abdel Latif | AK30: 14.5
AG31: Amr Hussein Hassan Mohamed Ali | AH31: 1 | AJ31: Amr Hussein Hassan Mohamed Ali | AK31: 5
AG32: Aya Khaled Naeem Elkhawaga | AH32: 1 | AJ32: Aya Khaled Naeem Elkhawaga | AK32: 12
AG33: Aya Sameh Hassan Ibrahim | AH33: 1 | AJ33: Aya Sameh Hassan Ibrahim | AK33: 5
AG34: Aya Tarek Mossad Abdelaziz | AH34: 1 | AJ34: Aya Tarek Mossad Abdelaziz | AK34: 10
AG35: Ayman Mousa Haneen Mokbel | AH35: 1 | AJ35: Ayman Mousa Haneen Mokbel | AK35: 2
AG36: Baher Saeed Khamis Mahmoud Elshamy | AH36: 1 | AJ36: Baher Saeed Khamis Mahmoud Elshamy | AK36: 9
AG37: Diana Hossam Abdelrahman Osman | AH37: 1 | AJ37: Diana Hossam Abdelrahman Osman | AK37: 21
AG38: Eleonora Christo Paraskevas Vostanis | AH38: 1 | AJ38: Eleonora Christo Paraskevas Vostanis | AK38: 14
AG39: eslam fathy abdelhamid mohamed | AH39: 1 | AJ39: eslam fathy abdelhamid mohamed | AK39: 15.5
AG40: Farouk Mohamed Farouk Soliman | AH40: 1 | AJ40: Farouk Mohamed Farouk Soliman | AK40: 1
...

Sheet Top Learner
A2: Learner | B2: Learning Hrs | C2: Department | D2: Linkedin hours | E2: Position | F2: Trophy
A3: Ahmed Gamal Mostafa Kamel | B3: 23 | C3: =VLOOKUP(A3,'Head Count 212'!B:L,11,0) -> MEP | E3: =VLOOKUP('Top Learner'!$A3,[1]Sheet1!$A:$F,6,0) -> MEP Design Section Head | F3: TL 1 | G3: 1500
A4: Shereen walaa mohamed askar | B4: 23 | C4: =VLOOKUP(A4,'Head Count 212'!B:L,11,0) -> Architecture | E4: =VLOOKUP('Top Learner'!$A4,[1]Sheet1!$A:$F,6,0) -> Design Management Section Head | F4: TM | G4: 2000
A5: Khadija Mohamed Ahmed Zayed | B5: 22 | C5: =VLOOKUP(A5,'Head Count 212'!B:L,11,0) -> Call Center | D5: 0.5 | E5: =VLOOKUP('Top Learner'!$A5,[1]Sheet1!$A:$F,6,0) -> Communication Center Representative | F5: TL 2 | G5: 1200
A6: Diana Hossam Abdelrahman Osman | B6: 21 | C6: =VLOOKUP(A6,'Head Count 212'!B:L,11,0) -> Design Management | E6: =VLOOKUP('Top Learner'!$A6,[1]Sheet1!$A:$F,6,0) -> Design Management Section Head | F6: TL 3 | G6: 900
A9: Row Labels | B9: Actual | C9: Planned
A10: Customised
A11: CCE | B11: 2
A12: Finance | B12: 2
A13: I&D | B13: 1
A14: L&D | B14: 1
A15: Projects | B15: 2
A16: Sales | B16: 5
A17: Public Calender
A18: (blank) | B18: 12
A19: Grand Total | B19: 25

Sheet Evaluation Pivots
D1: Completion Time | E1: (Multiple Items)
A3: Row Labels | B3: Average of FACILITATOR PERFORMANCE | D3: Row Labels | E3: Average of NPS | F3: Average of KNOWLEDGE RELVEANCE | G3: Average of LOGISTICS EFFECTIVNESS | H3: Average of ACTIVITY EFFECTIVNESS
A4: Ahmed ElShiaty | B4: 1 | D4: Hard Talks | E4: 1 | F4: 1 | G4: 1 | H4: 1
A5: Amr Alaa | B5: 1 | D5: Island of Seacrets-(Finance Dept) | E5: 1 | F5: 1 | G5: 1 | H5: 1
A6: Aya Sameh | B6: 1 | D6: Master The Shift | E6: 0.75 | F6: 1 | G6: 1 | H6: 1
A7: Grand Total | B7: 1 | D7: Parenting 101 | E7: 1 | F7: 1 | G7: 1 | H7: 1
D8: Self Discovery Lab | E8: 1 | F8: 1 | G8: 1 | H8: 1
D9: Story Craft | E9: 1 | F9: 1 | G9: 1 | H9: 1
D10: The Connected Leader | E10: 1 | F10: 1 | G10: 0.83333333 | H10: 0.91666667
D11: The Influence Map | E11: 0.72727273 | F11: 1 | G11: 1 | H11: 1
D12: Think Human | E12: 1 | F12: 1 | G12: 1 | H12: 1
D13: Grand Total | E13: 0.92727273 | F13: 1 | G13: 0.96363636 | H13: 0.98181818

Sheet Attendance Master Sheet
A1: # | B1: Enrollments | C1: Participation PC/Cust | D1: PC/Cust (Per Topic) | E1: Customised (Dept) | F1: Program Name | G1: Trainer Name | H1: Program Duration/hrs | I1: Learning Hrs | J1: No.of sessions | K1: Name | L1: Phone Number | M1: Email | N1: Department | O1: Job Title | P1: Employee Code | Q1: Date | R1: Internal/External | S1: Sector
A2: 1 | B2: 10 | C2: Public Calender | D2: Public Calender | F2: Self Discovery Lab | G2: Ahmed Magdi | H2: 2 | I2: 2 | J2: 2 | K2: Eleonora Christo Paraskevas Vostanis | L2: 01001483748 | M2: eleonora.christo@themarq.com.eg | N2: Content Writing | O2: Junior Content Writer | P2: TM4-16669 | Q2: 46076 | R2: Internal | S2: Marketing & PR
A3: 2 | C3: Public Calender | F3: Self Discovery Lab | G3: Ahmed Magdi | I3: 2 | K3: Aya Tarek Mossad Abdelaziz | L3: 01148322683 | M3: aya.tarek@themarq.com.eg | N3: Call Center | O3: Communication Center Representative | P3: TM4-21925 | Q3: 46076 | R3: Internal | S3: Communities & Clients Excellence
A4: 3 | C4: Public Calender | F4: Self Discovery Lab | G4: Ahmed Magdi | I4: 2 | K4: Mohamed Ahmed Abdallah Ahmed Sharaf | L4: 01285727056 | M4: mohamed.abdullah@themarq.com.eg | N4: Call Center | O4: Communication Center Representative | P4: TM4-32401 | Q4: 46076 | R4: Internal | S4: Communities & Clients Excellence
A5: 4 | C5: Public Calender | F5: Self Discovery Lab | G5: Ahmed Magdi | I5: 2 | K5: Khadija Mohamed Ahmed Zayed | L5: 1099170090 | M5: khadija.zayed@themarq.com.eg | N5: Call Center | O5: Communication Center Representative | P5: TM4-31843 | Q5: 46076 | R5: Internal | S5: Communities & Clients Excellence
A6: 5 | C6: Public Calender | F6: Self Discovery Lab | G6: Ahmed Magdi | H6: 2 | I6: 2 | K6: Mohamed Ahmed Abdallah Ahmed Sharaf | L6: 01285727056 | M6: mohamed.abdullah@themarq.com.eg | N6: Call Center | O6: Communication Center Representative | P6: TM4-32401 | Q6: 46077 | R6: Internal | S6: Communities & Clients Excellence
A7: 6 | C7: Public Calender | F7: Self Discovery Lab | G7: Ahmed Magdi | I7: 2 | K7: Aya Khaled Naeem Elkhawaga | L7: 01111879328 | M7: aya.elkhawaga@themarq.com.eg | N7: HR Business Partner | O7: HR Business Partner Supervisor | P7: TM4-32448 | Q7: 46077 | R7: Internal | S7: Human Resources
A8: 7 | C8: Public Calender | F8: Self Discovery Lab | G8: Ahmed Magdi | I8: 2 | K8: Mariam Ibrahim Mohamed Ibrahim | L8: 01007512970 | M8: mariam.ibrahim@themarq.com.eg | N8: HR Business Partner | O8: HR Business Partner Supervisor | P8: TM4-22886 | Q8: 46077 | R8: Internal | S8: Human Resources | W8: Row Labels | X8: Count of Name
A9: 8 | C9: Public Calender | F9: Self Discovery Lab | G9: Ahmed Magdi | I9: 2 | K9: Eleonora Christo Paraskevas Vostanis | L9: 01001483748 | M9: eleonora.christo@themarq.com.eg | N9: Content Writing | O9: Junior Content Writer | P9: TM4-16669 | Q9: 46077 | R9: Internal | S9: Marketing & PR | W9: Ai 4 Marq - AI Foundations - Wave 2 | X9: 5
A10: 9 | B10: 6 | C10: Customised | D10: Customised | E10: L&D | F10: HPI | G10: Yehia Maklad | H10: 5 | I10: 5 | J10: 1 | K10: Ahmed elsayed elsayed elshiaty | L10: 01006856836 | M10: ahmed.elshiaty@themarq.com.eg | N10: Learning & Development | O10: Learning & Development Director | P10: TM4-17746 | Q10: 46090 | R10: External | S10: Human Resources | W10: Ai 4 Marq - Level 1 | X10: 17
A11: 10 | C11: Customised | F11: HPI | G11: Yehia Maklad | I11: 5 | K11: Passant Magdy Abdel Razek Eliwa | L11: 01099691693 | M11: passant.magdy@themarq.com.eg | N11: Organization Development & Talent Management | O11: OD & Talent Management Director | P11: TM4-14720 | Q11: 46090 | R11: External | S11: Human Resources | W11: AI for real estate (Projects-D&I) | X11: 46
A12: 11 | C12: Customised | F12: HPI | G12: Yehia Maklad | I12: 5 | K12: Ahmed Magdy Fekry Elhagaa | L12: 01024642618 | M12: a.magdi@themarq.com.eg | N12: Learning & Development | O12: Learning & Development Manager | P12: TM4-21123 | Q12: 46090 | R12: External | S12: Human Resources | W12: Customer Focus | X12: 20
A13: 12 | C13: Customised | F13: HPI | G13: Yehia Maklad | I13: 5 | K13: Amr Alaa Eldin Maged Ahmed | L13: 01002527457 | M13: a.alaa@themarq.com.eg | N13: Learning & Development | O13: Learning & Development Manager | P13: TM4-21124 | Q13: 46090 | R13: External | S13: Human Resources | W13: Customer XP Cycle-CCE ONLY | X13: 26
A14: 13 | C14: Customised | F14: HPI | G14: Yehia Maklad | I14: 5 | K14: Aya Sameh Hassan Ibrahim | L14: 01015101500 | M14: aya.sameh@themarq.com.eg | N14: Learning & Development | O14: Learning & Development Manager | P14: TM4-27684 | Q14: 46090 | R14: External | S14: Human Resources | W14: Excel 101 | X14: 40
A15: 14 | C15: Customised | F15: HPI | G15: Yehia Maklad | I15: 5 | K15: Ahmad Mohamed Ahmad Mohamed Mansour | L15: 01115455761 | M15: ahmad.mansour@themarq.com.eg | N15: Organization Development & Talent Management | O15: Associate OD & Talent Management Manager | P15: TMC-33188 | Q15: 46090 | R15: External | S15: Human Resources | W15: Goal Setting &Building Habits -HS | X15: 9
A16: 15 | B16: 9 | C16: Public Calender | D16: Public Calender | F16: Think Human | G16: Aya Sameh | H16: 4 | I16: 4 | J16: 1 | K16: Mohamed Mabrouk Ismail Mohamed | L16: 01099262847 | M16: mohamed.mabrouk@themarq.com.eg | N16: Accounts Receivable | O16: Associate Accounts Receivable Manager | P16: TM4-8006 | Q16: 46097 | R16: Internal | S16: Finance | W16: Hard Talks | X16: 8
A17: 16 | C17: Public Calender | F17: Think Human | G17: Aya Sameh | I17: 4 | K17: Mohamed Hussein Yaqoub Mohamed | L17: 01093124080 | M17: mohamed.husien@themarq.com.eg | N17: Call Center | O17: Senior Communication Center Representative | P17: TM4-21494 | Q17: 46097 | R17: Internal | S17: Communities & Clients Excellence | W17: HPI | X17: 6
A18: 17 | C18: Public Calender | F18: Think Human | G18: Aya Sameh | I18: 4 | K18: MennatAllah Yahya Mohamed Tawfik Ahmed Abdul Aziz | L18: 01005397775 | M18: menna.yahya@themarq.com.eg | N18: Business Development | O18: Business Development Director | P18: TM4-15460 | Q18: 46097 | R18: Internal | S18: Commercial | W18: inside out | X18: 11
A19: 18 | B19: 10 | C19: Public Calender | D19: Public Calender | F19: Parenting 101 | G19: Aya Sameh | H19: 4 | I19: 4 | J19: 1 | K19: Aya Khaled Naeem Elkhawaga | L19: 01111879328 | M19: aya.elkhawaga@themarq.com.eg | N19: HR Business Partner | O19: HR Business Partner Supervisor | P19: TM4-32448 | Q19: 46112 | R19: Internal | S19: Human Resources | W19: Island of Seacrets-(Finance Dept) | X19: 11
A20: 19 | C20: Public Calender | F20: Parenting 101 | G20: Aya Sameh | I20: 4 | K20: Gehad Badr El Sayed Bayoumi | L20: 01277237484 | M20: gehad.badr@themarq.com.eg | N20: Accounts Receivable | O20: Accounts Receivable Supervisor | P20: TM4-8010 | Q20: 46112 | R20: Internal | S20: Finance | W20: LinkedIn Learning Kick-Off Session | X20: 16
A21: 20 | C21: Public Calender | F21: Parenting 101 | G21: Aya Sameh | I21: 4 | K21: Mohamed Mabrouk Ismail Mohamed | L21: 01099262847 | M21: mohamed.mabrouk@themarq.com.eg | N21: Accounts Receivable | O21: Associate Accounts Receivable Manager | P21: TM4-8006 | Q21: 46112 | R21: Internal | S21: Finance | W21: Master The Shift | X21: 17
A22: 21 | C22: Public Calender | F22: Parenting 101 | G22: Aya Sameh | I22: 4 | K22: Diana Hossam Abdelrahman Osman | L22: 01117139927 | M22: diana.elsehemy@themarq.com.eg | N22: Design Management | O22: Design Management Section Head | P22: TM4-19302 | Q22: 46112 | R22: Internal | S22: Development & Innovation | W22: Parenting 101 | X22: 9
A23: 22 | C23: Public Calender | F23: Parenting 101 | G23: Aya Sameh | I23: 4 | K23: Shereen walaa mohamed askar | L23: 01008039820 | M23: shereen.walaa@themarq.com.eg | N23: Architecture | O23: Architecture Design Review Section Head | P23: TM4-27126 | Q23: 46112 | R23: Internal | S23: Development & Innovation | W23: Presentation Skills-HS | X23: 7
A24: 23 | C24: Public Calender | F24: Parenting 101 | G24: Aya Sameh | I24: 4 | K24: Ahmed Gamal Mostafa Kamel | L24: 01102078925 | M24: ahmed.gamal@themarq.com.eg | N24: MEP | O24: MEP Design Review Section Head | P24: TM4-31608 | Q24: 46112 | R24: Internal | S24: Development & Innovation | W24: Sales Skills 1-HS | X24: 9
A25: 24 | C25: Public Calender | F25: Parenting 101 | G25: Aya Sameh | I25: 4 | K25: Mohamed Adel mohamed khader | L25: 01007764944 | M25: mohamed.khafaga@themarq.com.eg | N25: Call Center | O25: Communication Center Manager | P25: TM4-22654 | Q25: 46112 | R25: Internal | S25: Communities & Clients Excellence | W25: Sales Skills 2-HS | X25: 9
A26: 25 | C26: Public Calender | F26: Parenting 101 | G26: Aya Sameh | I26: 4 | K26: Nourhan yasser Hamed Elmoaz | L26: 01000461636 | M26: nourhan.yasser@themarq.com.eg | N26: Business Development | O26: Business Development Supervisor | P26: TM4-12569 | Q26: 46112 | R26: Internal | S26: Commercial | W26: Self Discovery Lab | X26: 8
A27: 26 | C27: Public Calender | F27: Parenting 101 | G27: Aya Sameh | I27: 4 | K27: MennatAllah Yahya Mohamed Tawfik Ahmed Abdul Aziz | L27: 01005397775 | M27: menna.yahya@themarq.com.eg | N27: Business Development | O27: Business Development Director | P27: TM4-15460 | Q27: 46112 | R27: Internal | S27: Commercial | W27: Slide Design | X27: 2
A28: 27 | B28: 12 | C28: Customised | D28: Customised | E28: Sales | F28: Goal Setting &Building Habits -HS | G28: Amr Alaa | H28: 5 | I28: 5 | J28: 1 | K28: Abdelaziz Youssef Abo El Wafa Mohamed | L28: 1023388233 | M28: abdelaziz.youssef@themarq.com.eg | N28: Sales | O28: Senior Property Consultant | P28: TM4-2456 | Q28: 46061 | R28: Internal | S28: Commercial | W28: Story Craft | X28: 17
A29: 28 | C29: Customised | F29: Goal Setting &Building Habits -HS | G29: Amr Alaa | I29: 5 | K29: Ahmed Khaled Kamal Ibrahim | L29: 1027108060 | M29: ahmed.kamal@themarq.com.eg | N29: Sales | O29: Senior Property Consultant | P29: TM4-14995 | Q29: 46061 | R29: Internal | S29: Commercial | W29: The Connected Leader | X29: 38
A30: 29 | C30: Customised | F30: Goal Setting &Building Habits -HS | G30: Amr Alaa | I30: 5 | K30: Ahmed Saber Abdelrady Mohamed | L30: 1005406501 | M30: ahmed.saber@themarq.com.eg | N30: Sales | O30: Senior Property Consultant | P30: N/A | Q30: 46061 | R30: Internal | S30: Commercial | W30: The Influence Map | X30: 35
A31: 30 | C31: Customised | F31: Goal Setting &Building Habits -HS | G31: Amr Alaa | I31: 5 | K31: Ahmed Samir Galal Elelemy Ahmed | L31: 1118099906 | M31: ahmed.jalal@themarq.com.eg | N31: Sales | O31: Property Consultant | P31: N/A | Q31: 46061 | R31: Internal | S31: Commercial | W31: The Influence Map (Projects) | X31: 40
A32: 31 | C32: Customised | F32: Goal Setting &Building Habits -HS | G32: Amr Alaa | I32: 5 | K32: Amr Ali Mahmoud Elhanbaly | L32: 1007939202 | M32: amr.elhanbaly@themarq.com.eg | N32: Sales | O32: Sales Supervisor | P32: N/A | Q32: 46061 | R32: Internal | S32: Commercial | W32: Think Human | X32: 3
A33: 32 | C33: Customised | F33: Goal Setting &Building Habits -HS | G33: Amr Alaa | I33: 5 | K33: Amr Hussein Hassan Mohamed Ali | L33: 1008910521 | M33: amr.hussien@themarq.com.eg | N33: Sales | O33: Sales Supervisor | P33: N/A | Q33: 46061 | R33: Internal | S33: Commercial | W33: Time &Self Management -HS | X33: 6
A34: 33 | C34: Customised | F34: Goal Setting &Building Habits -HS | G34: Amr Alaa | I34: 5 | K34: Tarnem Mohamed Mohamed El sherbini | L34: 1027390399 | M34: Tarneem.mohamed@themarq.com.eg | N34: Sales | O34: Sales Supervisor | P34: N/A | Q34: 46061 | R34: Internal | S34: Commercial | W34: Grand Total | X34: 415
A35: 34 | C35: Customised | F35: Goal Setting &Building Habits -HS | G35: Amr Alaa | I35: 5 | K35: Mahmoud Walid | L35: 1200028027 | M35: New Hire | N35: Sales | O35: Property Consultant | P35: N/A | Q35: 46061 | R35: Internal | S35: Commercial
A36: 35 | C36: Customised | F36: Goal Setting &Building Habits -HS | G36: Amr Alaa | I36: 5 | K36: Passant El Ghandour | L36: 1092254432 | M36: New Hire | N36: Sales | O36: Senior Property Consultant | P36: N/A | Q36: 46061 | R36: Internal | S36: Commercial
A37: 36 | B37: 12 | C37: Customised | D37: Customised | E37: Sales | F37: Sales Skills 1-HS | G37: Amr Alaa | H37: 5 | I37: 5 | J37: 1 | K37: Abdelaziz Youssef Abo El Wafa Mohamed | L37: 1023388233 | M37: abdelaziz.youssef@themarq.com.eg | N37: Sales | O37: Senior Property Consultant | P37: N/A | Q37: 46062 | R37: Internal | S37: Commercial
A38: 37 | C38: Customised | F38: Sales Skills 1-HS | G38: Amr Alaa | I38: 5 | K38: Ahmed Khaled Kamal Ibrahim | L38: 1027108060 | M38: ahmed.kamal@themarq.com.eg | N38: Sales | O38: Senior Property Consultant | P38: N/A | Q38: 46062 | R38: Internal | S38: Commercial
A39: 38 | C39: Customised | F39: Sales Skills 1-HS | G39: Amr Alaa | I39: 5 | K39: Ahmed Saber Abdelrady Mohamed | L39: 1005406501 | M39: ahmed.saber@themarq.com.eg | N39: Sales | O39: Senior Property Consultant | P39: N/A | Q39: 46062 | R39: Internal | S39: Commercial
A40: 39 | C40: Customised | F40: Sales Skills 1-HS | G40: Amr Alaa | I40: 5 | K40: Ahmed Samir Galal Elelemy Ahmed | L40: 1118099906 | M40: ahmed.jalal@themarq.com.eg | N40: Sales | O40: Property Consultant | P40: N/A | Q40: 46062 | R40: Internal | S40: Commercial
...

Sheet Sheet2

Sheet Evaluation Master Sheet
A1: Survey ID | B1: Start Time | C1: Completion Time | D1: Name | E1: Email | F1: Phone Number | G1: Topic Name | H1: Trainers | I1: Q1 - How relevant was the knowledge you gained throughout the training? | J1: Q2 - How effective were the learning activities used in this training? | K1: Q3 - How effective were the logistics (handouts, room, food, etc.) used in the training? | L1: Q4 - How would you rate the facilitator's overall performance? | M1: Q5 - How likely are you to recommend this training to a friend or teammate? | N1: Q6 - Mention any comments or suggestions to improve the overall learning experience | O1: PROMOTOR | P1: PASSIVE 1 | Q1: PASSIVE | R1: DETRACTOR | S1: Total Reponses | T1: NPS | U1: FACILITATOR PERFORMANCE | V1: ACTIVITY EFFECTIVNESS | W1: LOGISTICS EFFECTIVNESS | X1: KNOWLEDGE RELVEANCE
A2: 2 | B2: 46076.5 | C2: 46077.583 | D2: Mariam Ibrahim Mohamed Ibrahim | E2: mariam.ibrahim@themarq.com.eg | F2: 1007512970 | G2: Self Discovery Lab | H2: Ahmed Magdi | I2: 5 | J2: 5 | K2: 5 | L2: 5 | M2: 10 | O2: =IF(M2>=9,1,0) -> 1 | P2: =IF(M2>=7,1,0) -> 1 | Q2: =P2-O2 -> 0 | R2: =IF(M2<=6,1,0) -> 0 | S2: =O2+Q2+R2 -> 1 | T2: =((O2-R2)/S2) -> 1 | U2: =IF(L2>=4,1,0) -> 1 | V2: =IF(J2>=4,1,0) -> 1 | W2: =IF(K2>=4,1,0) -> 1 | X2: =IF(I2>=4,1,0) -> 1
A3: 2 | B3: 46076.5 | C3: 46077.583 | D3: Aya Khaled Naeem Elkhawaga | E3: aya.elkhawaga@themarq.com.eg | F3: 1111879328 | G3: Self Discovery Lab | H3: Ahmed Magdi | I3: 5 | J3: 5 | K3: 5 | L3: 5 | M3: 10 | O3: =IF(M3>=9,1,0) -> 1 | P3: =IF(M3>=7,1,0) -> 1 | Q3: =P3-O3 -> 0 | R3: =IF(M3<=6,1,0) -> 0 | S3: =O3+Q3+R3 -> 1 | T3: =((O3-R3)/S3) -> 1 | U3: =IF(L3>=4,1,0) -> 1 | V3: =IF(J3>=4,1,0) -> 1 | W3: =IF(K3>=4,1,0) -> 1 | X3: =IF(I3>=4,1,0) -> 1
A4: 2 | B4: 46076.5 | C4: 46077.583 | D4: Mohamed Ahmed Abdallah Ahmed Sharaf | E4: mohamed.abdullah@themarq.com.eg | F4: 1285727056 | G4: Self Discovery Lab | H4: Ahmed Magdi | I4: 5 | J4: 5 | K4: 5 | L4: 5 | M4: 10 | O4: =IF(M4>=9,1,0) -> 1 | P4: =IF(M4>=7,1,0) -> 1 | Q4: =P4-O4 -> 0 | R4: =IF(M4<=6,1,0) -> 0 | S4: =O4+Q4+R4 -> 1 | T4: =((O4-R4)/S4) -> 1 | U4: =IF(L4>=4,1,0) -> 1 | V4: =IF(J4>=4,1,0) -> 1 | W4: =IF(K4>=4,1,0) -> 1 | X4: =IF(I4>=4,1,0) -> 1
A5: 2 | B5: 46076.5 | C5: 46077.583 | D5: Eleonora Christo Paraskevas Vostanis | E5: eleonora.christo@themarq.com.eg | F5: 1001483748 | G5: Self Discovery Lab | H5: Ahmed Magdi | I5: 5 | J5: 4 | K5: 5 | L5: 5 | M5: 9 | O5: =IF(M5>=9,1,0) -> 1 | P5: =IF(M5>=7,1,0) -> 1 | Q5: =P5-O5 -> 0 | R5: =IF(M5<=6,1,0) -> 0 | S5: =O5+Q5+R5 -> 1 | T5: =((O5-R5)/S5) -> 1 | U5: =IF(L5>=4,1,0) -> 1 | V5: =IF(J5>=4,1,0) -> 1 | W5: =IF(K5>=4,1,0) -> 1 | X5: =IF(I5>=4,1,0) -> 1
A6: 2 | B6: 46097.5 | C6: 46098.583 | D6: Khadija Mohamed Ahmed Zayed | E6: khadija.zayed@themarq.com.eg | F6: 1099170090 | G6: Think Human | H6: Aya Sameh | I6: 5 | J6: 5 | K6: 5 | L6: 5 | M6: 10 | N6: nothing | O6: =IF(M6>=9,1,0) -> 1 | P6: =IF(M6>=7,1,0) -> 1 | Q6: =P6-O6 -> 0 | R6: =IF(M6<=6,1,0) -> 0 | S6: =O6+Q6+R6 -> 1 | T6: =((O6-R6)/S6) -> 1 | U6: =IF(L6>=4,1,0) -> 1 | V6: =IF(J6>=4,1,0) -> 1 | W6: =IF(K6>=4,1,0) -> 1 | X6: =IF(I6>=4,1,0) -> 1
A7: 2 | B7: 46097.5 | C7: 46098.583 | D7: Mohamed Hussein Yaqoub Mohamed | E7: mohamed.husien@themarq.com.eg | F7: 1093124080 | G7: Think Human | H7: Aya Sameh | I7: 5 | J7: 5 | K7: 5 | L7: 5 | M7: 10 | O7: =IF(M7>=9,1,0) -> 1 | P7: =IF(M7>=7,1,0) -> 1 | Q7: =P7-O7 -> 0 | R7: =IF(M7<=6,1,0) -> 0 | S7: =O7+Q7+R7 -> 1 | T7: =((O7-R7)/S7) -> 1 | U7: =IF(L7>=4,1,0) -> 1 | V7: =IF(J7>=4,1,0) -> 1 | W7: =IF(K7>=4,1,0) -> 1 | X7: =IF(I7>=4,1,0) -> 1
A8: 2 | B8: 46097.5 | C8: 46098.583 | D8: MennatAllah Yahya Mohamed Tawfik Ahmed Abdul Aziz | E8: menna.yahya@themarq.com.eg | F8: 1005397775 | G8: Think Human | H8: Aya Sameh | I8: 5 | J8: 5 | K8: 5 | L8: 5 | M8: 10 | N8: Extending the duration would allow for better coverage and understanding. | O8: =IF(M8>=9,1,0) -> 1 | P8: =IF(M8>=7,1,0) -> 1 | Q8: =P8-O8 -> 0 | R8: =IF(M8<=6,1,0) -> 0 | S8: =O8+Q8+R8 -> 1 | T8: =((O8-R8)/S8) -> 1 | U8: =IF(L8>=4,1,0) -> 1 | V8: =IF(J8>=4,1,0) -> 1 | W8: =IF(K8>=4,1,0) -> 1 | X8: =IF(I8>=4,1,0) -> 1
A9: 2 | B9: 46097.5 | C9: 46098.583 | D9: Mohamed Mabrouk Ismail Mohamed | E9: mohamed.mabrouk@themarq.com.eg | F9: 1099262847 | G9: Think Human | H9: Aya Sameh | I9: 5 | J9: 5 | K9: 5 | L9: 5 | M9: 10 | O9: =IF(M9>=9,1,0) -> 1 | P9: =IF(M9>=7,1,0) -> 1 | Q9: =P9-O9 -> 0 | R9: =IF(M9<=6,1,0) -> 0 | S9: =O9+Q9+R9 -> 1 | T9: =((O9-R9)/S9) -> 1 | U9: =IF(L9>=4,1,0) -> 1 | V9: =IF(J9>=4,1,0) -> 1 | W9: =IF(K9>=4,1,0) -> 1 | X9: =IF(I9>=4,1,0) -> 1
A10: 2 | B10: 46112.5 | C10: 46112.625 | D10: MennatAllah Yahya Mohamed Tawfik Ahmed Abdul Aziz | E10: menna.yahya@themarq.com.eg | F10: 1005397775 | G10: Parenting 101 | H10: Aya Sameh | I10: 5 | J10: 5 | K10: 5 | L10: 5 | M10: 10 | O10: =IF(M10>=9,1,0) -> 1 | P10: =IF(M10>=7,1,0) -> 1 | Q10: =P10-O10 -> 0 | R10: =IF(M10<=6,1,0) -> 0 | S10: =O10+Q10+R10 -> 1 | T10: =((O10-R10)/S10) -> 1 | U10: =IF(L10>=4,1,0) -> 1 | V10: =IF(J10>=4,1,0) -> 1 | W10: =IF(K10>=4,1,0) -> 1 | X10: =IF(I10>=4,1,0) -> 1
A11: 2 | B11: 46112.5 | C11: 46112.625 | D11: Gehad Badr El Sayed Bayoumi | E11: gehad.badr@themarq.com.eg | F11: 1277237484 | G11: Parenting 101 | H11: Aya Sameh | I11: 5 | J11: 5 | K11: 5 | L11: 5 | M11: 10 | O11: =IF(M11>=9,1,0) -> 1 | P11: =IF(M11>=7,1,0) -> 1 | Q11: =P11-O11 -> 0 | R11: =IF(M11<=6,1,0) -> 0 | S11: =O11+Q11+R11 -> 1 | T11: =((O11-R11)/S11) -> 1 | U11: =IF(L11>=4,1,0) -> 1 | V11: =IF(J11>=4,1,0) -> 1 | W11: =IF(K11>=4,1,0) -> 1 | X11: =IF(I11>=4,1,0) -> 1
A12: 2 | B12: 46112.5 | C12: 46112.625 | D12: Mohamed Mabrouk Ismail Mohamed | E12: mohamed.mabrouk@themarq.com.eg | F12: 1099262847 | G12: Parenting 101 | H12: Aya Sameh | I12: 5 | J12: 5 | K12: 5 | L12: 5 | M12: 10 | N12: Excellent thanks a lot | O12: =IF(M12>=9,1,0) -> 1 | P12: =IF(M12>=7,1,0) -> 1 | Q12: =P12-O12 -> 0 | R12: =IF(M12<=6,1,0) -> 0 | S12: =O12+Q12+R12 -> 1 | T12: =((O12-R12)/S12) -> 1 | U12: =IF(L12>=4,1,0) -> 1 | V12: =IF(J12>=4,1,0) -> 1 | W12: =IF(K12>=4,1,0) -> 1 | X12: =IF(I12>=4,1,0) -> 1
A13: 2 | B13: 46112.5 | C13: 46112.625 | D13: Nourhan yasser Hamed Elmoaz | E13: nourhan.yasser@themarq.com.eg | F13: 1000461636 | G13: Parenting 101 | H13: Aya Sameh | I13: 5 | J13: 5 | K13: 5 | L13: 5 | M13: 10 | O13: =IF(M13>=9,1,0) -> 1 | P13: =IF(M13>=7,1,0) -> 1 | Q13: =P13-O13 -> 0 | R13: =IF(M13<=6,1,0) -> 0 | S13: =O13+Q13+R13 -> 1 | T13: =((O13-R13)/S13) -> 1 | U13: =IF(L13>=4,1,0) -> 1 | V13: =IF(J13>=4,1,0) -> 1 | W13: =IF(K13>=4,1,0) -> 1 | X13: =IF(I13>=4,1,0) -> 1
A14: 2 | B14: 46112.5 | C14: 46112.625 | D14: Diana Hossam Abdelrahman Osman | E14: diana.elsehemy@themarq.com.eg | F14: 1117139927 | G14: Parenting 101 | H14: Aya Sameh | I14: 4 | J14: 5 | K14: 5 | L14: 5 | M14: 9 | O14: =IF(M14>=9,1,0) -> 1 | P14: =IF(M14>=7,1,0) -> 1 | Q14: =P14-O14 -> 0 | R14: =IF(M14<=6,1,0) -> 0 | S14: =O14+Q14+R14 -> 1 | T14: =((O14-R14)/S14) -> 1 | U14: =IF(L14>=4,1,0) -> 1 | V14: =IF(J14>=4,1,0) -> 1 | W14: =IF(K14>=4,1,0) -> 1 | X14: =IF(I14>=4,1,0) -> 1
A15: 2 | B15: 46112.5 | C15: 46112.625 | D15: Ahmed Gamal Mostafa Kamel | E15: ahmed.gamal@themarq.com.eg | F15: 1102078925 | G15: Parenting 101 | H15: Aya Sameh | I15: 5 | J15: 5 | K15: 5 | L15: 5 | M15: 10 | O15: =IF(M15>=9,1,0) -> 1 | P15: =IF(M15>=7,1,0) -> 1 | Q15: =P15-O15 -> 0 | R15: =IF(M15<=6,1,0) -> 0 | S15: =O15+Q15+R15 -> 1 | T15: =((O15-R15)/S15) -> 1 | U15: =IF(L15>=4,1,0) -> 1 | V15: =IF(J15>=4,1,0) -> 1 | W15: =IF(K15>=4,1,0) -> 1 | X15: =IF(I15>=4,1,0) -> 1
A16: 2 | B16: 46112.5 | C16: 46112.625 | D16: Aya Khaled Naeem Elkhawaga | E16: aya.elkhawaga@themarq.com.eg | F16: 1111879328 | G16: Parenting 101 | H16: Aya Sameh | I16: 5 | J16: 5 | K16: 5 | L16: 5 | M16: 10 | O16: =IF(M16>=9,1,0) -> 1 | P16: =IF(M16>=7,1,0) -> 1 | Q16: =P16-O16 -> 0 | R16: =IF(M16<=6,1,0) -> 0 | S16: =O16+Q16+R16 -> 1 | T16: =((O16-R16)/S16) -> 1 | U16: =IF(L16>=4,1,0) -> 1 | V16: =IF(J16>=4,1,0) -> 1 | W16: =IF(K16>=4,1,0) -> 1 | X16: =IF(I16>=4,1,0) -> 1
A17: 2 | B17: 46112.5 | C17: 46112.625 | D17: Shereen walaa mohamed askar | E17: shereen.walaa@themarq.com.eg | F17: 1008039820 | G17: Parenting 101 | H17: Aya Sameh | I17: 5 | J17: 5 | K17: 5 | L17: 5 | M17: 10 | O17: =IF(M17>=9,1,0) -> 1 | P17: =IF(M17>=7,1,0) -> 1 | Q17: =P17-O17 -> 0 | R17: =IF(M17<=6,1,0) -> 0 | S17: =O17+Q17+R17 -> 1 | T17: =((O17-R17)/S17) -> 1 | U17: =IF(L17>=4,1,0) -> 1 | V17: =IF(J17>=4,1,0) -> 1 | W17: =IF(K17>=4,1,0) -> 1 | X17: =IF(I17>=4,1,0) -> 1
A18: 2 | B18: 46133.479 | C18: 46134.583 | D18: Alaa Essam Mohamed Ibrahim | E18: alaa.omar@themarq.com.eg | F18: 1117559150 | G18: Master The Shift | H18: Aya Sameh | I18: 5 | J18: 5 | K18: 5 | L18: 5 | M18: 10 | O18: =IF(M18>=9,1,0) -> 1 | P18: =IF(M18>=7,1,0) -> 1 | Q18: =P18-O18 -> 0 | R18: =IF(M18<=6,1,0) -> 0 | S18: =O18+Q18+R18 -> 1 | T18: =((O18-R18)/S18) -> 1 | U18: =IF(L18>=4,1,0) -> 1 | V18: =IF(J18>=4,1,0) -> 1 | W18: =IF(K18>=4,1,0) -> 1 | X18: =IF(I18>=4,1,0) -> 1
A19: 2 | B19: 46133.479 | C19: 46134.583 | D19: Nour Eldin Fathy Mohamed Khaky | E19: nour.fathy@themarq.com.eg | F19: 1029867676 | G19: Master The Shift | H19: Aya Sameh | I19: 5 | J19: 5 | K19: 5 | L19: 5 | M19: 10 | O19: =IF(M19>=9,1,0) -> 1 | P19: =IF(M19>=7,1,0) -> 1 | Q19: =P19-O19 -> 0 | R19: =IF(M19<=6,1,0) -> 0 | S19: =O19+Q19+R19 -> 1 | T19: =((O19-R19)/S19) -> 1 | U19: =IF(L19>=4,1,0) -> 1 | V19: =IF(J19>=4,1,0) -> 1 | W19: =IF(K19>=4,1,0) -> 1 | X19: =IF(I19>=4,1,0) -> 1
A20: 2 | B20: 46133.479 | C20: 46134.583 | D20: Youssef Ehab Kamal AbdelHady Ahmed | E20: youssef.eldairy@themarq.com.eg | F20: 1094298431 | G20: Master The Shift | H20: Aya Sameh | I20: 5 | J20: 5 | K20: 5 | L20: 5 | M20: 10 | O20: =IF(M20>=9,1,0) -> 1 | P20: =IF(M20>=7,1,0) -> 1 | Q20: =P20-O20 -> 0 | R20: =IF(M20<=6,1,0) -> 0 | S20: =O20+Q20+R20 -> 1 | T20: =((O20-R20)/S20) -> 1 | U20: =IF(L20>=4,1,0) -> 1 | V20: =IF(J20>=4,1,0) -> 1 | W20: =IF(K20>=4,1,0) -> 1 | X20: =IF(I20>=4,1,0) -> 1
A21: 2 | B21: 46133.479 | C21: 46134.583 | D21: Ahmed Gamal Mostafa Kamel | E21: ahmed.gamal@themarq.com.eg | F21: 1102078925 | G21: Master The Shift | H21: Aya Sameh | I21: 4 | J21: 4 | K21: 4 | L21: 5 | M21: 8 | O21: =IF(M21>=9,1,0) -> 0 | P21: =IF(M21>=7,1,0) -> 1 | Q21: =P21-O21 -> 1 | R21: =IF(M21<=6,1,0) -> 0 | S21: =O21+Q21+R21 -> 1 | T21: =((O21-R21)/S21) -> 0 | U21: =IF(L21>=4,1,0) -> 1 | V21: =IF(J21>=4,1,0) -> 1 | W21: =IF(K21>=4,1,0) -> 1 | X21: =IF(I21>=4,1,0) -> 1
A22: 2 | B22: 2026-05-11 10:00:00 | C22: 2026-05-13 13:00:00 | D22: eslam fathy abdelhamid mohamed | E22: eslam.fathyy@themarq.com.eg | F22: 01090348691 | G22: The Influence Map | H22: Ahmed ElShiaty | I22: 5 | J22: 5 | K22: 5 | L22: 5 | M22: 10 | N22: nothing everything is awesome | O22: =IF(M22>=9,1,0) -> 1 | P22: =IF(M22>=7,1,0) -> 1 | Q22: =P22-O22 -> 0 | R22: =IF(M22<=6,1,0) -> 0 | S22: =O22+Q22+R22 -> 1 | T22: =((O22-R22)/S22) -> 1 | U22: =IF(L22>=4,1,0) -> 1 | V22: =IF(J22>=4,1,0) -> 1 | W22: =IF(K22>=4,1,0) -> 1 | X22: =IF(I22>=4,1,0) -> 1
A23: 2 | B23: 2026-05-11 10:00:00 | C23: 2026-05-13 13:00:00 | D23: Abdelrahman Mohamed Saad Ahmed | E23: abdelrahman.saad@themarq.com.eg | F23: 01150812762 | G23: The Influence Map | H23: Ahmed ElShiaty | I23: 4 | J23: 4 | K23: 4 | L23: 5 | M23: 8 | N23: very good | O23: =IF(M23>=9,1,0) -> 0 | P23: =IF(M23>=7,1,0) -> 1 | Q23: =P23-O23 -> 1 | R23: =IF(M23<=6,1,0) -> 0 | S23: =O23+Q23+R23 -> 1 | T23: =((O23-R23)/S23) -> 0 | U23: =IF(L23>=4,1,0) -> 1 | V23: =IF(J23>=4,1,0) -> 1 | W23: =IF(K23>=4,1,0) -> 1 | X23: =IF(I23>=4,1,0) -> 1
A24: 2 | B24: 2026-05-11 10:00:00 | C24: 2026-05-13 13:00:00 | D24: Mosaad Abd El hameed Mohamed Abd elhameed | E24: mosaad.abdelhameed@themarq.com.eg | F24: 01222750776 | G24: The Influence Map | H24: Ahmed ElShiaty | I24: 5 | J24: 5 | K24: 4 | L24: 4 | M24: 7 | O24: =IF(M24>=9,1,0) -> 0 | P24: =IF(M24>=7,1,0) -> 1 | Q24: =P24-O24 -> 1 | R24: =IF(M24<=6,1,0) -> 0 | S24: =O24+Q24+R24 -> 1 | T24: =((O24-R24)/S24) -> 0 | U24: =IF(L24>=4,1,0) -> 1 | V24: =IF(J24>=4,1,0) -> 1 | W24: =IF(K24>=4,1,0) -> 1 | X24: =IF(I24>=4,1,0) -> 1
A25: 2 | B25: 2026-05-11 10:00:00 | C25: 2026-05-13 13:00:00 | D25: Mahmoud Alaa Eldin Elsayed Abdelmaged | E25: mahmoud.alaa@themarq.com.eg | F25: 01147760466 | G25: The Influence Map | H25: Ahmed ElShiaty | I25: 5 | J25: 5 | K25: 5 | L25: 5 | M25: 10 | N25: very very talented team | O25: =IF(M25>=9,1,0) -> 1 | P25: =IF(M25>=7,1,0) -> 1 | Q25: =P25-O25 -> 0 | R25: =IF(M25<=6,1,0) -> 0 | S25: =O25+Q25+R25 -> 1 | T25: =((O25-R25)/S25) -> 1 | U25: =IF(L25>=4,1,0) -> 1 | V25: =IF(J25>=4,1,0) -> 1 | W25: =IF(K25>=4,1,0) -> 1 | X25: =IF(I25>=4,1,0) -> 1
A26: 2 | B26: 2026-05-11 10:00:00 | C26: 2026-05-13 13:00:00 | D26: Mostafa Ali Abdelmohsen Mohamed | E26: mostafa.ali@themarq.com.eg | F26: 01140171761 | G26: The Influence Map | H26: Ahmed ElShiaty | I26: 4 | J26: 4 | K26: 4 | L26: 4 | M26: 8 | O26: =IF(M26>=9,1,0) -> 0 | P26: =IF(M26>=7,1,0) -> 1 | Q26: =P26-O26 -> 1 | R26: =IF(M26<=6,1,0) -> 0 | S26: =O26+Q26+R26 -> 1 | T26: =((O26-R26)/S26) -> 0 | U26: =IF(L26>=4,1,0) -> 1 | V26: =IF(J26>=4,1,0) -> 1 | W26: =IF(K26>=4,1,0) -> 1 | X26: =IF(I26>=4,1,0) -> 1
A27: 2 | B27: 2026-05-11 10:00:00 | C27: 2026-05-13 13:00:00 | D27: Mahmoud Gamal Mahmoud Aboulila | E27: mahmoud.abulila@themarq.com.eg | F27: 01125565819 | G27: The Influence Map | H27: Ahmed ElShiaty | I27: 5 | J27: 5 | K27: 5 | L27: 4 | M27: 10 | O27: =IF(M27>=9,1,0) -> 1 | P27: =IF(M27>=7,1,0) -> 1 | Q27: =P27-O27 -> 0 | R27: =IF(M27<=6,1,0) -> 0 | S27: =O27+Q27+R27 -> 1 | T27: =((O27-R27)/S27) -> 1 | U27: =IF(L27>=4,1,0) -> 1 | V27: =IF(J27>=4,1,0) -> 1 | W27: =IF(K27>=4,1,0) -> 1 | X27: =IF(I27>=4,1,0) -> 1
A28: 2 | B28: 2026-05-11 10:00:00 | C28: 2026-05-13 13:00:00 | D28: Hany Refaat Abdallah Mohamed | E28: hany.refaat@themarq.com.eg | F28: 01156170952 | G28: The Influence Map | H28: Ahmed ElShiaty | I28: 5 | J28: 5 | K28: 5 | L28: 5 | M28: 10 | O28: =IF(M28>=9,1,0) -> 1 | P28: =IF(M28>=7,1,0) -> 1 | Q28: =P28-O28 -> 0 | R28: =IF(M28<=6,1,0) -> 0 | S28: =O28+Q28+R28 -> 1 | T28: =((O28-R28)/S28) -> 1 | U28: =IF(L28>=4,1,0) -> 1 | V28: =IF(J28>=4,1,0) -> 1 | W28: =IF(K28>=4,1,0) -> 1 | X28: =IF(I28>=4,1,0) -> 1
A29: 2 | B29: 2026-05-11 10:00:00 | C29: 2026-05-13 13:00:00 | D29: Gehad Badr El Sayed Bayoumi | E29: gehad.badr@themarq.com.eg | F29: 01277237484 | G29: The Influence Map | H29: Ahmed ElShiaty | I29: 5 | J29: 5 | K29: 5 | L29: 5 | M29: 10 | O29: =IF(M29>=9,1,0) -> 1 | P29: =IF(M29>=7,1,0) -> 1 | Q29: =P29-O29 -> 0 | R29: =IF(M29<=6,1,0) -> 0 | S29: =O29+Q29+R29 -> 1 | T29: =((O29-R29)/S29) -> 1 | U29: =IF(L29>=4,1,0) -> 1 | V29: =IF(J29>=4,1,0) -> 1 | W29: =IF(K29>=4,1,0) -> 1 | X29: =IF(I29>=4,1,0) -> 1
A30: 2 | B30: 2026-05-11 10:00:00 | C30: 2026-05-13 13:00:00 | D30: Khadija Mohamed Ahmed Zayed | E30: khadija.zayed@themarq.com.eg | F30: 1099170090 | G30: The Influence Map | H30: Ahmed ElShiaty | I30: 5 | J30: 5 | K30: 5 | L30: 5 | M30: 10 | O30: =IF(M30>=9,1,0) -> 1 | P30: =IF(M30>=7,1,0) -> 1 | Q30: =P30-O30 -> 0 | R30: =IF(M30<=6,1,0) -> 0 | S30: =O30+Q30+R30 -> 1 | T30: =((O30-R30)/S30) -> 1 | U30: =IF(L30>=4,1,0) -> 1 | V30: =IF(J30>=4,1,0) -> 1 | W30: =IF(K30>=4,1,0) -> 1 | X30: =IF(I30>=4,1,0) -> 1
A31: 2 | B31: 2026-05-11 10:00:00 | C31: 2026-05-13 13:00:00 | D31: Moustafa Salah Mohamed Hassan | E31: mostafa.salah@themarq.com.eg | F31: 01201082999 | G31: The Influence Map | H31: Ahmed ElShiaty | I31: 5 | J31: 5 | K31: 5 | L31: 5 | M31: 10 | O31: =IF(M31>=9,1,0) -> 1 | P31: =IF(M31>=7,1,0) -> 1 | Q31: =P31-O31 -> 0 | R31: =IF(M31<=6,1,0) -> 0 | S31: =O31+Q31+R31 -> 1 | T31: =((O31-R31)/S31) -> 1 | U31: =IF(L31>=4,1,0) -> 1 | V31: =IF(J31>=4,1,0) -> 1 | W31: =IF(K31>=4,1,0) -> 1 | X31: =IF(I31>=4,1,0) -> 1
A32: 2 | B32: 2026-05-11 10:00:00 | C32: 2026-05-13 13:00:00 | D32: MennatAllah Yahya Mohamed Tawfik Ahmed Abdul Aziz | E32: menna.yahya@themarq.com.eg | F32: 01005397775 | G32: The Influence Map | H32: Ahmed ElShiaty | I32: 5 | J32: 5 | K32: 5 | L32: 5 | M32: 10 | O32: =IF(M32>=9,1,0) -> 1 | P32: =IF(M32>=7,1,0) -> 1 | Q32: =P32-O32 -> 0 | R32: =IF(M32<=6,1,0) -> 0 | S32: =O32+Q32+R32 -> 1 | T32: =((O32-R32)/S32) -> 1 | U32: =IF(L32>=4,1,0) -> 1 | V32: =IF(J32>=4,1,0) -> 1 | W32: =IF(K32>=4,1,0) -> 1 | X32: =IF(I32>=4,1,0) -> 1
A33: 2 | B33: 2026-05-19 11:00:00 | C33: 2026-05-20 14:00:00 | D33: Magy Safwat Abdelsayed Ayyad Elbyady | E33: magy.safwat@themarq.com.eg | F33: 01224070029 | G33: The Connected Leader | H33: Ahmed Elshiaty | I33: 5 | J33: 3 | K33: 5 | L33: 5 | M33: 9 | O33: =IF(M33>=9,1,0) -> 1 | P33: =IF(M33>=7,1,0) -> 1 | Q33: =P33-O33 -> 0 | R33: =IF(M33<=6,1,0) -> 0 | S33: =O33+Q33+R33 -> 1 | T33: =((O33-R33)/S33) -> 1 | U33: =IF(L33>=4,1,0) -> 1 | V33: =IF(J33>=4,1,0) -> 0 | W33: =IF(K33>=4,1,0) -> 1 | X33: =IF(I33>=4,1,0) -> 1
A34: 2 | B34: 2026-05-19 11:00:00 | C34: 2026-05-20 14:00:00 | D34: Ahmed Medhat Sayed Baioumy el Atbany | E34: ahmed.medhat@themarq.com.eg | F34: 01285342768 | G34: The Connected Leader | H34: Ahmed Elshiaty | I34: 4 | J34: 4 | K34: 4 | L34: 5 | M34: 9 | O34: =IF(M34>=9,1,0) -> 1 | P34: =IF(M34>=7,1,0) -> 1 | Q34: =P34-O34 -> 0 | R34: =IF(M34<=6,1,0) -> 0 | S34: =O34+Q34+R34 -> 1 | T34: =((O34-R34)/S34) -> 1 | U34: =IF(L34>=4,1,0) -> 1 | V34: =IF(J34>=4,1,0) -> 1 | W34: =IF(K34>=4,1,0) -> 1 | X34: =IF(I34>=4,1,0) -> 1
A35: 2 | B35: 2026-05-19 11:00:00 | C35: 2026-05-20 14:00:00 | D35: eslam fathy abdelhamid mohamed | E35: eslam.fathyy@themarq.com.eg | F35: 01090348691 | G35: The Connected Leader | H35: Ahmed Elshiaty | I35: 4 | J35: 5 | K35: 4 | L35: 5 | M35: 10 | O35: =IF(M35>=9,1,0) -> 1 | P35: =IF(M35>=7,1,0) -> 1 | Q35: =P35-O35 -> 0 | R35: =IF(M35<=6,1,0) -> 0 | S35: =O35+Q35+R35 -> 1 | T35: =((O35-R35)/S35) -> 1 | U35: =IF(L35>=4,1,0) -> 1 | V35: =IF(J35>=4,1,0) -> 1 | W35: =IF(K35>=4,1,0) -> 1 | X35: =IF(I35>=4,1,0) -> 1
A36: 2 | B36: 2026-05-19 11:00:00 | C36: 2026-05-20 14:00:00 | D36: Ahmed kamal El Din Hassan El Khateeb | E36: ahmed.elkhateeb@themarq.com.eg | F36: 01110005077 | G36: The Connected Leader | H36: Ahmed Elshiaty | I36: 4 | J36: 5 | K36: 4 | L36: 5 | M36: 10 | O36: =IF(M36>=9,1,0) -> 1 | P36: =IF(M36>=7,1,0) -> 1 | Q36: =P36-O36 -> 0 | R36: =IF(M36<=6,1,0) -> 0 | S36: =O36+Q36+R36 -> 1 | T36: =((O36-R36)/S36) -> 1 | U36: =IF(L36>=4,1,0) -> 1 | V36: =IF(J36>=4,1,0) -> 1 | W36: =IF(K36>=4,1,0) -> 1 | X36: =IF(I36>=4,1,0) -> 1
A37: 2 | B37: 2026-05-19 11:00:00 | C37: 2026-05-20 14:00:00 | D37: Abdelrahman Ismail Abdallah Elshahat | E37: abdelrahman.ismail@themarq.com.eg | F37: 01001709593 | G37: The Connected Leader | H37: Ahmed Elshiaty | I37: 5 | J37: 5 | K37: 3 | L37: 5 | M37: 9 | O37: =IF(M37>=9,1,0) -> 1 | P37: =IF(M37>=7,1,0) -> 1 | Q37: =P37-O37 -> 0 | R37: =IF(M37<=6,1,0) -> 0 | S37: =O37+Q37+R37 -> 1 | T37: =((O37-R37)/S37) -> 1 | U37: =IF(L37>=4,1,0) -> 1 | V37: =IF(J37>=4,1,0) -> 1 | W37: =IF(K37>=4,1,0) -> 0 | X37: =IF(I37>=4,1,0) -> 1
... A45: 2 | B45: 2026-06-03 11:30:00 | C45: 2026-06-04 14:00:00 | D45: Ahmed Samir Galal Elelemy Ahmed | E45: ahmed.jalal@themarq.com.eg | F45: 01118099906 | G45: Story Craft | H45: Amr Alaa | I45: 5 | J45: 5 | K45: 5 | L45: 5 | M45: 10 | O45: =IF(M45>=9,1,0) -> 1 | P45: =IF(M45>=7,1,0) -> 1 | Q45: =P45-O45 -> 0 | R45: =IF(M45<=6,1,0) -> 0 | S45: =O45+Q45+R45 -> 1 | T45: =((O45-R45)/S45) -> 1 | U45: =IF(L45>=4,1,0) -> 1 | V45: =IF(J45>=4,1,0) -> 1 | W45: =IF(K45>=4,1,0) -> 1 | X45: =IF(I45>=4,1,0) -> 1
A46: 2 | B46: 2026-06-03 11:30:00 | C46: 2026-06-04 14:00:00 | D46: Omar Amr Mohamed Adel | E46: omar.amr@themarq.com.eg | F46: 1140535256 | G46: Story Craft | H46: Amr Alaa | I46: 4 | J46: 5 | K46: 5 | L46: 5 | M46: 10 | N46: more sessions and applications | O46: =IF(M46>=9,1,0) -> 1 | P46: =IF(M46>=7,1,0) -> 1 | Q46: =P46-O46 -> 0 | R46: =IF(M46<=6,1,0) -> 0 | S46: =O46+Q46+R46 -> 1 | T46: =((O46-R46)/S46) -> 1 | U46: =IF(L46>=4,1,0) -> 1 | V46: =IF(J46>=4,1,0) -> 1 | W46: =IF(K46>=4,1,0) -> 1 | X46: =IF(I46>=4,1,0) -> 1
A47: 2 | B47: 2026-06-03 11:30:00 | C47: 2026-06-04 14:00:00 | D47: Ahmed kamal El Din Hassan El Khateeb | E47: ahmed.elkhateeb@themarq.com.eg | F47: 01110005077 | G47: Story Craft | H47: Amr Alaa | I47: 5 | J47: 5 | K47: 5 | L47: 5 | M47: 10 | N47: thank you! | O47: =IF(M47>=9,1,0) -> 1 | P47: =IF(M47>=7,1,0) -> 1 | Q47: =P47-O47 -> 0 | R47: =IF(M47<=6,1,0) -> 0 | S47: =O47+Q47+R47 -> 1 | T47: =((O47-R47)/S47) -> 1 | U47: =IF(L47>=4,1,0) -> 1 | V47: =IF(J47>=4,1,0) -> 1 | W47: =IF(K47>=4,1,0) -> 1 | X47: =IF(I47>=4,1,0) -> 1
...

Sheet Linked In no
I1: Linked In above 10mins | J1: Unique in Class
B2: Inclass | C2: Linked In | D2: Uniques | F2: Inclass | G2: =B95 -> 92 | I2: Abdelrahman Ismail | J2: Abdelaziz Youssef Abo El Wafa Mohamed
A3: Inclass | B3: Abdelaziz Youssef Abo El Wafa Mohamed | C3: Shady Amir Ahmed Mirdan | D3: Abdelaziz Youssef Abo El Wafa Mohamed | F3: Linked In | G3: =C30 -> 27 | I3: Abdelrhman Amer | J3: Abdelrahman Ismail Abdallah Elshahat
A4: Inclass | B4: Abdelrahman Ismail Abdallah Elshahat | C4: Ahmed Raouf Abdel Menaam Hanafy | D4: Abdelrahman Ismail Abdallah Elshahat | F4: Uniques | G4: =D101 -> 98 | I4: Afef Rizk | J4: Abdelrahman Khaled Saber Mohamed
A5: Inclass | B5: Abdelrahman Khaled Saber Mohamed | C5: Youssef Hussien Abdelrahman Abdelmeged | D5: Abdelrahman Khaled Saber Mohamed | I5: Ahmed Elkhateeb | J5: Abdelrahman Mohamed Saad Ahmed
A6: Inclass | B6: Abdelrahman Mohamed Saad Ahmed | C6: Moustafa Salah Mohamed Hassan | D6: Abdelrahman Mohamed Saad Ahmed | I6: Ahmed Jalal | J6: Ahmad Mohamed Ahmad Mohamed Mansour
A7: Inclass | B7: Ahmad Mohamed Ahmad Mohamed Mansour | C7: Seif Mohamed Abd El Halim | D7: Ahmad Mohamed Ahmad Mohamed Mansour | I7: Ahmed Magdi | J7: Ahmed Abdel Hakim
A8: Inclass | B8: Ahmed Abdel Hakim | C8: Abdelrahman Amer Abdelrahman Ahmed | D8: Ahmed Abdel Hakim | I8: Ahmed Raouf | J8: Ahmed AlaaEldin Abdelhalim Ismail Keshk
A9: Inclass | B9: Ahmed elsayed elsayed elshiaty | C9: Amr Alaa Eldin Maged Ahmed | D9: Ahmed elsayed elsayed elshiaty | I9: Aida Fouad | J9: Ahmed elsayed elsayed elshiaty
A10: Inclass | B10: Ahmed Gamal Mostafa Kamel | C10: Israa Mahmoud Elsayed Maraie | D10: Ahmed Gamal Mostafa Kamel | I10: Amr Alaa | J10: Ahmed Gamal Mostafa Kamel
A11: Inclass | B11: Ahmed kamal El Din Hassan El Khateeb | C11: MennatAllah Yahya Mohamed Tawfik Ahmed Abdul Aziz | D11: Ahmed kamal El Din Hassan El Khateeb | I11: Amr Hany | J11: Ahmed kamal El Din Hassan El Khateeb
A12: Inclass | B12: Ahmed Khaled Kamal Ibrahim | C12: Abdelrahman Ismail Abdallah Elshahat | D12: Ahmed Khaled Kamal Ibrahim | I12: Aya Sameh | J12: Ahmed Khaled Kamal Ibrahim
A13: Inclass | B13: Ahmed Magdy Fekry Elhagaa | C13: Amr Hani Mohamed Abdel Latif | D13: Ahmed Magdy Fekry Elhagaa | I13: Eslam Fathyy | J13: Ahmed Magdy Fekry Elhagaa
A14: Inclass | B14: Ahmed Medhat Sayed Baioumy el Atbany | C14: Mohamed Hussein Yaqoub Mohamed | D14: Ahmed Medhat Sayed Baioumy el Atbany | I14: Gehad Badr | J14: Ahmed Medhat Sayed Baioumy el Atbany
A15: Inclass | B15: Ahmed mohamed AboelMagd Eldardiri | C15: Mohamed Adel mohamed khader | D15: Ahmed mohamed AboelMagd Eldardiri | I15: Hany Refaat | J15: Ahmed mohamed AboelMagd Eldardiri
A16: Inclass | B16: Ahmed Mohamed Ahmed Salem | C16: Ahmed kamal El Din Hassan El Khateeb | D16: Ahmed Mohamed Ahmed Salem | I16: Israa Marie | J16: Ahmed Mohamed Ahmed Salem
... A29: Inclass | B29: Amr Hani Mohamed Abdel Latif | C29: Mohamed Mabrouk Ismail Mohamed | D29: Amr Hani Mohamed Abdel Latif | I29: Mostafa Salah | J29: Amira Tarek Mohamed Abdelmutaal Ali El Sherkawy
A30: Inclass | B30: Amr Hussein Hassan Mohamed Ali | C30: 27 | D30: Amr Hussein Hassan Mohamed Ali | I30: Seif Mohamed | J30: Amr Alaa Eldin Maged Ahmed
A31: Inclass | B31: Aya Khaled Naeem Elkhawaga | D31: Aya Khaled Naeem Elkhawaga | I31: Shady Amir | J31: Abdelaziz Ali Bakr Abdelaziz
A32: Inclass | B32: Aya Sameh Hassan Ibrahim | D32: Aya Sameh Hassan Ibrahim | I32: Toaa Ghanem | J32: Amr Ali Abdelwahab Sobh
A33: Inclass | B33: Aya Tarek Mossad Abdelaziz | D33: Aya Tarek Mossad Abdelaziz | I33: Yousef Hussin | J33: Amr Ali Mahmoud Elhanbaly
A34: Inclass | B34: Ayman Mousa Haneen Mokbel | D34: Ayman Mousa Haneen Mokbel | J34: Amr Hani Mohamed Abdel Latif
A35: Inclass | B35: Baher Saeed Khamis Mahmoud Elshamy | D35: Baher Saeed Khamis Mahmoud Elshamy | J35: Amr Hussein Hassan Mohamed Ali
A36: Inclass | B36: Diana Hossam Abdelrahman Osman | D36: Diana Hossam Abdelrahman Osman | J36: Aya Hussein Omar Ahmed
A37: Inclass | B37: Eleonora Christo Paraskevas Vostanis | D37: Eleonora Christo Paraskevas Vostanis | J37: Aya Karim Thomas Konstantin
A38: Inclass | B38: eslam fathy abdelhamid mohamed | D38: eslam fathy abdelhamid mohamed | J38: Aya Khaled Naeem Elkhawaga
A39: Inclass | B39: Farouk Mohamed Farouk Soliman | D39: Farouk Mohamed Farouk Soliman | J39: Aya Sameh Hassan Ibrahim
A40: Inclass | B40: Gehad Badr El Sayed Bayoumi | D40: Gehad Badr El Sayed Bayoumi | J40: Aya Tarek Mossad Abdelaziz
A41: Inclass | B41: Gihan Mohamed Labib Abdelbasset Auf | D41: Gihan Mohamed Labib Abdelbasset Auf | J41: Ayman Mostafa Yousri Ahmed Mohamed
A42: Inclass | B42: Hamed Ramadan Aliu Abdel Aal | D42: Hamed Ramadan Aliu Abdel Aal | J42: Ayman Mousa Haneen Mokbel
A43: Inclass | B43: Hany Refaat Abdallah Mohamed | D43: Hany Refaat Abdallah Mohamed | J43: Baher Saeed Khamis Mahmoud Elshamy
A44: Inclass | B44: heba ashraf youssef ibrahim | D44: heba ashraf youssef ibrahim | J44: Diana Hossam Abdelrahman Osman
A45: Inclass | B45: Heba Magdy Elbialy Hashish | D45: Heba Magdy Elbialy Hashish | J45: Eleonora Christo Paraskevas Vostanis
... A94: Inclass | B94: Youssef Hussien Abdelrahman Abdelmeged | D94: Youssef Hussien Abdelrahman Abdelmeged | J94: Mostafa Ali Abdelmohsen Mohamed
B95: 92 | D95: Shady Amir Ahmed Mirdan | J95: Moustafa Salah Mohamed Hassan
D96: Seif Mohamed Abd El Halim | J96: Nadeem Nabil Ahmed Fahmy
D97: Abdelrahman Amer Abdelrahman Ahmed | J97: Noha Hassan Sabry Mohamed Ibrahim
D98: Karim Mohamed Othman Hassan | J98: Nour Eldin Fathy Mohamed Khaky
D99: Khaled Mohamed El-mesilhy Mohamed Ibrahim | J99: Nour Sherif Mohamed Hussien Abbas
D100: Atef Rezk El Sayed El Sayed El Sabbagh | J100: Nourhan yasser Hamed Elmoaz
...

Sheet Attendance Prep
A1: # | B1: Enrollments | C1: Participation PC/Cust | D1: PC/Cust (Per Topic) | E1: Customised (Dept) | F1: Program Name | G1: Trainer Name | H1: Program Duration/hrs | I1: Learning Hrs | J1: No.of sessions | K1: Name | L1: Phone Number | M1: Email | N1: Department | O1: Job Title | P1: Employee Code | Q1: Date | R1: Internal/External | S1: Sector
A2: Session ID | F2: Program Name | G2: Trainer Name | H2: Duration | K2: Name | L2: Phone Number | M2: Email | N2: Department | O2: Job Title | P2: Employee Code | Q2: Attendance Date
A3: 165 | B3: 6 | C3: Customised (Dept) | D3: Customised (Dept) | E3: Projects | F3: inside out | G3: Amr Alaa | H3: 3 | I3: 3 | J3: 2 | K3: Ayman Mostafa Yousri Ahmed Mohamed | L3: 01008352815 | M3: ayman.yosri@themarq.com.eg | N3: Tendering | O3: Associate Tendering Manager | P3: TMC-33778 | Q3: 46237 | R3: Internal | S3: Projects
A4: 165 | C4: Customised | F4: inside out | G4: Amr Alaa | I4: 3 | K4: Aya Hussein Omar Ahmed | L4: 01097201809 | M4: aya.hussien@themarq.com.eg | N4: Budgeting & Cost Control | O4: Associate Budgeting & Cost Control Manager | P4: TMC-33936 | Q4: 46237 | R4: Internal | S4: Projects
A5: 165 | C5: Customised | F5: inside out | G5: Amr Alaa | I5: 3 | K5: Maged Mostafa morsi attia | L5: 01224298898 | M5: maged.mostafa@themarq.com.eg | N5: Construction Project Management | O5: Senior Project Manager | P5: TM4-15486 | Q5: 46237 | R5: Internal | S5: Projects
A6: 165 | C6: Customised | F6: inside out | G6: Amr Alaa | I6: 3 | K6: AlShimaa Ahmed Mohamed Abdullatif | L6: 01000002740 | M6: alshimaa.abdullatif@themarq.com.eg | N6: Contracts | O6: Senior Contracts Manager | P6: TMC-33781 | Q6: 46237 | R6: Internal | S6: Projects
A7: 165 | C7: Customised | F7: inside out | G7: Amr Alaa | I7: 3 | K7: Israa Mahmoud Elsayed Maraie | L7: 01224692381 | M7: israa.maraie@themarq.com.eg | N7: Tendering | O7: Senior Tendering Manager | P7: TM4-25001 | Q7: 46237 | R7: Internal | S7: Projects
A8: 165 | C8: Customised | F8: inside out | G8: Amr Alaa | I8: 3 | K8: Ahmed AlaaEldin Abdelhalim Ismail Keshk | L8: 01015506230 | M8: ahmed.keshk@themarq.com.eg | N8: Budgeting & Cost Control | O8: Senior Budgeting & Cost Control Engineer | P8: TM4-32770 | Q8: 46237 | R8: Internal | S8: Projects
A9: 166 | C9: Customised | F9: inside out | G9: Amr Alaa | H9: 3 | I9: 3 | K9: Aya Hussein Omar Ahmed | L9: 01097201809 | M9: aya.hussien@themarq.com.eg | N9: Budgeting & Cost Control | O9: Associate Budgeting & Cost Control Manager | P9: TMC-33936 | Q9: 46240 | R9: Internal | S9: Projects
A10: 166 | C10: Customised | F10: inside out | G10: Amr Alaa | I10: 3 | K10: Maged Mostafa morsi attia | L10: 01224298898 | M10: maged.mostafa@themarq.com.eg | N10: Construction Project Management | O10: Senior Project Manager | P10: TM4-15486 | Q10: 46240 | R10: Internal | S10: Projects
A11: 166 | C11: Customised | F11: inside out | G11: Amr Alaa | I11: 3 | K11: Ayman Mostafa Yousri Ahmed Mohamed | L11: 01008352815 | M11: ayman.yosri@themarq.com.eg | N11: Tendering | O11: Associate Tendering Manager | P11: TMC-33778 | Q11: 46240 | R11: Internal | S11: Projects
A12: 166 | C12: Customised | F12: inside out | G12: Amr Alaa | I12: 3 | K12: AlShimaa Ahmed Mohamed Abdullatif | L12: 01000002740 | M12: alshimaa.abdullatif@themarq.com.eg | N12: Contracts | O12: Senior Contracts Manager | P12: TMC-33781 | Q12: 46240 | R12: Internal | S12: Projects
A13: 166 | C13: Customised | F13: inside out | G13: Amr Alaa | I13: 3 | K13: Israa Mahmoud Elsayed Maraie | L13: 01224692381 | M13: israa.maraie@themarq.com.eg | N13: Tendering | O13: Senior Tendering Manager | P13: TM4-25001 | Q13: 46240 | R13: Internal | S13: Projects

Sheet Head Count 212
A1: id | B1: full_name | C1: email | D1: mobile | E1: status | F1: company | G1: franchise | H1: sector | L1: department | M1: parent | N1: identification_id | O1: position | P1: employee_code | Q1: hire_date | R1: payscale_cluster_name | S1: payscale_cluster_code | T1: job_level_name | U1: job_level_grade | V1: allocation_company
A2: 8 | B2: Ahmed Hamdy Mohamed Abdelftah Mostafa Awaimar | C2: ahmed.hamdy@themarq.com.eg | D2: 01004379643 | E2: active | F2: The MarQ Communities | H2: Finance | I2: Credit Control | L2: Credit Control | M2: Efrayem Refaat Hanna Shalaby | N2: 28706191401617 | O2: Credit Control Director | P2: TM4-8031 | Q2: 2021-02-15 | R2: Executive Management | S2: 2 | T2: Director | U2: 17 | V2: The MarQ Communities
A3: 11 | B3: Ahmed Mohamed Adel Taha Abdelaal | C3: ahmed.adel@themarq.com.eg | D3: 01228233334 | E3: active | F3: The MarQ Communities | H3: Finance | I3: Credit Control | L3: Credit Control | M3: Ahmed Hamdy Mohamed Abdelftah Mostafa Awaimar | N3: 28911221300091 | O3: Credit Control Manager | P3: TM4-8032 | Q3: 2021-02-17 | R3: Middle Management | S3: 3 | T3: Manager | U3: 14 | V3: The MarQ Communities
